<?xml version="1.0" ?>
<!-- =================================================================================== -->
<!-- |    This document was autogenerated by xacro from braccio_arm.urdf               | -->
<!-- |    EDITING THIS FILE BY HAND IS NOT RECOMMENDED                                 | -->
<!-- =================================================================================== -->
<!-- =================================================================================== -->
<!-- |    This document was autogenerated by xacro from src/braccio_arduino_ros_rviz/urdf/braccio_arm.xacro | -->
<!-- |    EDITING THIS FILE BY HAND IS NOT RECOMMENDED                                 | -->
<!-- =================================================================================== -->
<robot name="braccio" xmlns:xacro="http://www.ros.org/wiki/xacro">

  <xacro:property name="camera_link" value="0.05" /> <!-- Size of square 'camera' box -->
  <xacro:property name="damping_value" value="0.1"/>
  <xacro:property name="friction_value" value="0.001"/>

    <link name="base_link">
    <visual>
      <geometry>
	<cylinder length="0.01" radius=".053" />
      </geometry>
      <material name="black"/>
      <origin rpy="0 0 0" xyz="0 0 0"/>
    </visual>
    <inertial>
      <mass value="2"/>
	<inertia ixx="0.015" ixy="0" ixz="0" iyy="0.00666666666667" iyz="0" izz="0.0216666666667"/>
    </inertial>
  </link>

    <link name="camera_link">
	<visual>	
		<geometry>
	            <box>
	              <size>0.073 0.276 0.072</size>
	            </box>
	        </geometry>
	<origin xyz="1.4 0 0.1" rpy="0 0 0"/>	
	</visual>

	<collision>	
		<geometry>
	            <box>
	              <size>0.073 0.276 0.072</size>
	            </box>
	          </geometry>
	<origin xyz="1.4 0 0.1" rpy="0 0 0"/>	
	</collision>
      <material name="orange"/>
    </link>

  <joint name="camera_joint" type="fixed">
	<origin xyz="1.4 0 0.1" rpy="0 0 0"/>	
    <parent link="base_link"/>
    <child link="camera_link"/>
  </joint>
  
  <link name="braccio_base_link">
    <visual>
      <geometry>
        <mesh filename="package://braccio_arduino_ros_rviz/stl/braccio_base.stl" scale="0.001 0.001 0.001"/>
      </geometry>
      <material name="orange"/>
      <origin rpy="0 0 3.1416" xyz="0 0.004 0" />
    </visual>
    <inertial>
      <mass value="2"/>
      <inertia ixx="0.015" ixy="0" ixz="0" iyy="0.00666666666667" iyz="0" izz="0.0216666666667"/>
    </inertial>
    <collision>
      <origin rpy="0 0 3.1416" xyz="0 0.004 0"/>
      <geometry>
        <mesh filename="package://braccio_arduino_ros_rviz/stl/braccio_base.stl" scale="0.001 0.001 0.001"/>
      </geometry>
    </collision>
  </link>
  <link name="shoulder_link">
    <visual>
      <geometry>
        <mesh filename="package://braccio_arduino_ros_rviz/stl/braccio_shoulder.stl" scale="0.001 0.001 0.001"/>
      </geometry>
      <material name="orange"/>
      <origin rpy="0 0 0" xyz="-0.0045 0.0055 -0.026"/>
    </visual>
    <inertial>
      <mass value="0.1"/>
      <inertia ixx="0.000348958333333" ixy="0" ixz="0" iyy="0.000348958333333" iyz="0" izz="3.125e-05"/>
    </inertial>
    <collision>
      <origin rpy="0 0 0" xyz="-0.0045 0.0055 -0.026"/>
      <geometry>
        <mesh filename="package://braccio_arduino_ros_rviz/stl/braccio_base.stl" scale="0.001 0.001 0.001"/>
      </geometry>
    </collision>
  </link>
  <link name="elbow_link">
    <visual>
      <geometry>
        <mesh filename="package://braccio_arduino_ros_rviz/stl/braccio_elbow.stl" scale="0.001 0.001 0.001"/>
      </geometry>
      <material name="orange"/>
      <origin rpy="0 0 0" xyz="-0.0045 0.005 -0.025"/>
    </visual>
    <inertial>
      <mass value="0.1"/>
      <inertia ixx="0.000348958333333" ixy="0" ixz="0" iyy="0.000348958333333" iyz="0" izz="3.125e-05"/>
    </inertial>
    <collision>
      <origin rpy="0 0 0" xyz="-0.0045 0.005 -0.025"/>
      <geometry>
        <mesh filename="package://braccio_arduino_ros_rviz/stl/braccio_elbow.stl" scale="0.001 0.001 0.001"/>
      </geometry>
    </collision>
  </link>
  <link name="wrist_pitch_link">
    <visual>
      <geometry>
        <mesh filename="package://braccio_arduino_ros_rviz/stl/braccio_wrist_pitch.stl" scale="0.001 0.001 0.001"/>
      </geometry>
      <material name="orange"/>
      <origin rpy="0 0 0" xyz="0.003 -0.0004 -0.024"/>
    </visual>
    <inertial>
      <mass value="0.1"/>
      <inertia ixx="0.000348958333333" ixy="0" ixz="0" iyy="0.000348958333333" iyz="0" izz="3.125e-05"/>
    </inertial>
    <collision>
      <origin rpy="0 0 0" xyz="0.003 -0.0004 -0.024"/>
      <geometry>
        <mesh filename="package://braccio_arduino_ros_rviz/stl/braccio_wrist_pitch.stl" scale="0.001 0.001 0.001"/>
      </geometry>
    </collision>
  </link>
  <link name="wrist_roll_link">
    <visual>
      <geometry>
        <mesh filename="package://braccio_arduino_ros_rviz/stl/braccio_wrist_roll.stl" scale="0.001 0.001 0.001"/>
      </geometry>
      <material name="white"/>
      <origin rpy="0 0 0" xyz="0.006 0 0.0"/>
    </visual>
    <inertial>
      <mass value="0.1"/>
      <inertia ixx="0.000348958333333" ixy="0" ixz="0" iyy="0.000348958333333" iyz="0" izz="3.125e-05"/>
    </inertial>
    <collision>
      <origin rpy="0 0 0" xyz="0.006 0 0.0"/>
      <geometry>
        <mesh filename="package://braccio_arduino_ros_rviz/stl/braccio_wrist_roll.stl" scale="0.001 0.001 0.001"/>
      </geometry>
    </collision>
  </link>
  <link name="left_gripper_link">
    <visual>
      <geometry>
        <mesh filename="package://braccio_arduino_ros_rviz/stl/braccio_left_gripper.stl" scale="0.001 0.001 0.001"/>
      </geometry>
      <material name="white"/>
      <origin rpy="0 1.5708 0" xyz="0 -0.012 0"/>
    </visual>
    <inertial>
      <mass value="0.1"/>
      <inertia ixx="0.000348958333333" ixy="0" ixz="0" iyy="0.000348958333333" iyz="0" izz="3.125e-05"/>
    </inertial>
    <collision>
      <origin rpy="0 1.5708 0" xyz="0 -0.012 0"/>
      <geometry>
        <mesh filename="package://braccio_arduino_ros_rviz/stl/braccio_left_gripper.stl" scale="0.001 0.001 0.001"/>
      </geometry>
    </collision>
  </link>
  <link name="right_gripper_link">
    <visual>
      <geometry>
        <mesh filename="package://braccio_arduino_ros_rviz/stl/braccio_right_gripper.stl" scale="0.001 0.001 0.001"/>
      </geometry>
      <material name="white"/>
      <origin rpy="0 1.5708 0" xyz="0 -0.012 0.010"/>
    </visual>
    <inertial>
      <mass value="0.1"/>
      <inertia ixx="0.000348958333333" ixy="0" ixz="0" iyy="0.000348958333333" iyz="0" izz="3.125e-05"/>
    </inertial>
    <collision>
      <origin rpy="0 1.5708 0" xyz="0 -0.012 0.010"/>
      <geometry>
        <mesh filename="package://braccio_arduino_ros_rviz/stl/braccio_right_gripper.stl" scale="0.001 0.001 0.001"/>
      </geometry>
    </collision>
  </link>
  <joint name="base_joint" type="revolute">
    <axis xyz="0 0 1"/>
    <limit effort="1000.0" lower="0.0" upper="3.1416" velocity="1.0"/>
    <origin rpy="0 0 0" xyz="0 0 0"/>
    <parent link="base_link"/>
    <child link="braccio_base_link"/>
    <dynamics damping="${damping_value}" friction="${friction_value}"/>
  </joint>
  <joint name="shoulder_joint" type="revolute">
    <axis xyz="1 0 0"/>
    <limit effort="1000.0" lower="0.2618" upper="2.8798" velocity="1.0"/>
    <origin rpy="-1.5708 0 0" xyz="0 -.002 0.072"/>
    <parent link="braccio_base_link"/>
    <child link="shoulder_link"/>
    <dynamics damping="${damping_value}" friction="${friction_value}"/>
  </joint>
  <joint name="elbow_joint" type="revolute">
    <axis xyz="1 0 0"/>
    <limit effort="1000.0" lower="0" upper="3.1416" velocity="1.0"/>
    <origin rpy="-1.5708 0 0" xyz="0 0 0.125"/>
    <parent link="shoulder_link"/>
    <child link="elbow_link"/>
    <dynamics damping="${damping_value}" friction="${friction_value}"/>
  </joint>
  <joint name="wrist_pitch_joint" type="revolute">
    <axis xyz="1 0 0"/>
    <limit effort="1000.0" lower="0" upper="3.1416" velocity="1.0"/>
    <origin rpy="-1.5708 0 0" xyz="0 0 0.125"/>
    <parent link="elbow_link"/>
    <child link="wrist_pitch_link"/>
    <dynamics damping="${damping_value}" friction="${friction_value}"/>
  </joint>
  <joint name="wrist_roll_joint" type="revolute">
    <axis xyz="0 0 -1"/>
    <limit effort="1000.0" lower="0.0" upper="3.1416" velocity="1.0"/>
    <origin rpy="0 0 1.5708" xyz="0 0.0 0.06"/>
    <parent link="wrist_pitch_link"/>
    <child link="wrist_roll_link"/>
    <dynamics damping="${damping_value}" friction="${friction_value}"/>
  </joint>
  <joint name="gripper_joint" type="revolute">
    <axis xyz="0 -1 0"/>
    <limit effort="1000.0" lower="0.1750" upper="1.2741" velocity="1.0"/>
    <origin rpy="0 -0.2967 0" xyz="0.010 0 0.03"/>
    <parent link="wrist_roll_link"/>
    <child link="right_gripper_link"/>
    <dynamics damping="${damping_value}" friction="${friction_value}"/>
  </joint>
  <joint name="sub_gripper_joint" type="revolute">
    <axis xyz="0 1 0"/>
    <mimic joint="gripper_joint"/>
    <limit effort="1000.0" lower="1.2741" upper="2.3732" velocity="1.0"/>
    <origin rpy="0 3.4383 0" xyz="-0.010 0 0.03"/>
    <parent link="wrist_roll_link"/>
    <child link="left_gripper_link"/>
    <dynamics damping="${damping_value}" friction="${friction_value}"/>
  </joint>
  <material name="orange">
    <color rgba="0.57 0.17 0.0 1"/>
  </material>
  <material name="white">
    <color rgba="0.8 0.8 0.8 1.0"/>
  </material>
  <material name="black">
    <color rgba="0 0 0 0.50"/>
  </material>

</robot>
